2022-07-26 12:06:19,071 INFO: Microblog startup [in /home/alexey/PycharmProjects/flaskProject/application/__init__.py:30]
2022-07-26 12:09:49,838 INFO: Microblog startup [in /home/alexey/PycharmProjects/flaskProject/application/__init__.py:30]
2022-07-26 12:11:52,630 INFO: Microblog startup [in /home/alexey/PycharmProjects/flaskProject/application/__init__.py:30]
2022-07-26 12:14:27,456 INFO: Microblog startup [in /home/alexey/PycharmProjects/flaskProject/application/__init__.py:30]
2022-07-26 12:14:30,494 ERROR: Exception on /dimension [GET] [in /home/alexey/PycharmProjects/flaskProject/venv/lib/python3.8/site-packages/flask/app.py:1455]
Traceback (most recent call last):
  File "/home/alexey/PycharmProjects/flaskProject/venv/lib/python3.8/site-packages/flask/app.py", line 2077, in wsgi_app
    response = self.full_dispatch_request()
  File "/home/alexey/PycharmProjects/flaskProject/venv/lib/python3.8/site-packages/flask/app.py", line 1525, in full_dispatch_request
    rv = self.handle_user_exception(e)
  File "/home/alexey/PycharmProjects/flaskProject/venv/lib/python3.8/site-packages/flask/app.py", line 1523, in full_dispatch_request
    rv = self.dispatch_request()
  File "/home/alexey/PycharmProjects/flaskProject/venv/lib/python3.8/site-packages/flask/app.py", line 1509, in dispatch_request
    return self.ensure_sync(self.view_functions[rule.endpoint])(**req.view_args)
  File "/home/alexey/PycharmProjects/flaskProject/venv/lib/python3.8/site-packages/flask_login/utils.py", line 303, in decorated_view
    return current_app.ensure_sync(func)(*args, **kwargs)
  File "/home/alexey/PycharmProjects/flaskProject/application/routes.py", line 99, in dimension
    if UploadForm.is_submitted():
TypeError: is_submitted() missing 1 required positional argument: 'self'
2022-07-26 12:14:56,590 INFO: Microblog startup [in /home/alexey/PycharmProjects/flaskProject/application/__init__.py:30]
2022-07-26 12:16:41,763 INFO: Microblog startup [in /home/alexey/PycharmProjects/flaskProject/application/__init__.py:30]
2022-07-26 12:23:16,616 INFO: Microblog startup [in /home/alexey/PycharmProjects/flaskProject/application/__init__.py:30]
2022-07-26 12:48:46,323 INFO: Microblog startup [in /home/alexey/PycharmProjects/flaskProject/application/__init__.py:30]
2022-07-26 12:49:37,958 INFO: Microblog startup [in /home/alexey/PycharmProjects/flaskProject/application/__init__.py:30]
2022-07-26 12:50:10,591 INFO: Microblog startup [in /home/alexey/PycharmProjects/flaskProject/application/__init__.py:30]
2022-07-26 12:57:32,457 INFO: Microblog startup [in /home/alexey/PycharmProjects/flaskProject/application/__init__.py:30]
2022-07-26 12:57:37,962 ERROR: Exception on /user/b [POST] [in /home/alexey/PycharmProjects/flaskProject/venv/lib/python3.8/site-packages/flask/app.py:1455]
Traceback (most recent call last):
  File "/home/alexey/PycharmProjects/flaskProject/venv/lib/python3.8/site-packages/flask/app.py", line 2077, in wsgi_app
    response = self.full_dispatch_request()
  File "/home/alexey/PycharmProjects/flaskProject/venv/lib/python3.8/site-packages/flask/app.py", line 1525, in full_dispatch_request
    rv = self.handle_user_exception(e)
  File "/home/alexey/PycharmProjects/flaskProject/venv/lib/python3.8/site-packages/flask/app.py", line 1523, in full_dispatch_request
    rv = self.dispatch_request()
  File "/home/alexey/PycharmProjects/flaskProject/venv/lib/python3.8/site-packages/flask/app.py", line 1509, in dispatch_request
    return self.ensure_sync(self.view_functions[rule.endpoint])(**req.view_args)
  File "/home/alexey/PycharmProjects/flaskProject/venv/lib/python3.8/site-packages/flask_login/utils.py", line 303, in decorated_view
    return current_app.ensure_sync(func)(*args, **kwargs)
  File "/home/alexey/PycharmProjects/flaskProject/application/routes.py", line 67, in user
    create_file()
  File "/home/alexey/PycharmProjects/flaskProject/application/create_files.py", line 16, in create_file
    canvas.drawImage()
TypeError: drawImage() missing 3 required positional arguments: 'image', 'x', and 'y'
2022-07-26 12:57:52,246 INFO: Microblog startup [in /home/alexey/PycharmProjects/flaskProject/application/__init__.py:30]
2022-07-26 12:57:57,215 ERROR: Exception on /user/b [POST] [in /home/alexey/PycharmProjects/flaskProject/venv/lib/python3.8/site-packages/flask/app.py:1455]
Traceback (most recent call last):
  File "/home/alexey/PycharmProjects/flaskProject/venv/lib/python3.8/site-packages/flask/app.py", line 2077, in wsgi_app
    response = self.full_dispatch_request()
  File "/home/alexey/PycharmProjects/flaskProject/venv/lib/python3.8/site-packages/flask/app.py", line 1525, in full_dispatch_request
    rv = self.handle_user_exception(e)
  File "/home/alexey/PycharmProjects/flaskProject/venv/lib/python3.8/site-packages/flask/app.py", line 1523, in full_dispatch_request
    rv = self.dispatch_request()
  File "/home/alexey/PycharmProjects/flaskProject/venv/lib/python3.8/site-packages/flask/app.py", line 1509, in dispatch_request
    return self.ensure_sync(self.view_functions[rule.endpoint])(**req.view_args)
  File "/home/alexey/PycharmProjects/flaskProject/venv/lib/python3.8/site-packages/flask_login/utils.py", line 303, in decorated_view
    return current_app.ensure_sync(func)(*args, **kwargs)
  File "/home/alexey/PycharmProjects/flaskProject/application/routes.py", line 67, in user
    create_file()
  File "/home/alexey/PycharmProjects/flaskProject/application/create_files.py", line 21, in create_file
    f = Table(data)
  File "/home/alexey/PycharmProjects/flaskProject/venv/lib/python3.8/site-packages/reportlab/platypus/tables.py", line 296, in __init__
    self._cellvalues = data = self.normalizeData(data)
  File "/home/alexey/PycharmProjects/flaskProject/venv/lib/python3.8/site-packages/reportlab/platypus/tables.py", line 389, in normalizeData
    outRow = [normCell(cell) for cell in row]
TypeError: 'int' object is not iterable
2022-07-26 12:58:32,701 INFO: Microblog startup [in /home/alexey/PycharmProjects/flaskProject/application/__init__.py:30]
2022-07-26 12:58:59,770 INFO: Microblog startup [in /home/alexey/PycharmProjects/flaskProject/application/__init__.py:30]
2022-07-26 13:03:27,505 INFO: Microblog startup [in /home/alexey/PycharmProjects/flaskProject/application/__init__.py:30]
2022-07-26 13:10:09,746 INFO: Microblog startup [in /home/alexey/PycharmProjects/flaskProject/application/__init__.py:30]
2022-07-26 13:10:16,593 ERROR: Exception on /user/b [POST] [in /home/alexey/PycharmProjects/flaskProject/venv/lib/python3.8/site-packages/flask/app.py:1455]
Traceback (most recent call last):
  File "/home/alexey/PycharmProjects/flaskProject/venv/lib/python3.8/site-packages/flask/app.py", line 2077, in wsgi_app
    response = self.full_dispatch_request()
  File "/home/alexey/PycharmProjects/flaskProject/venv/lib/python3.8/site-packages/flask/app.py", line 1525, in full_dispatch_request
    rv = self.handle_user_exception(e)
  File "/home/alexey/PycharmProjects/flaskProject/venv/lib/python3.8/site-packages/flask/app.py", line 1523, in full_dispatch_request
    rv = self.dispatch_request()
  File "/home/alexey/PycharmProjects/flaskProject/venv/lib/python3.8/site-packages/flask/app.py", line 1509, in dispatch_request
    return self.ensure_sync(self.view_functions[rule.endpoint])(**req.view_args)
  File "/home/alexey/PycharmProjects/flaskProject/venv/lib/python3.8/site-packages/flask_login/utils.py", line 303, in decorated_view
    return current_app.ensure_sync(func)(*args, **kwargs)
  File "/home/alexey/PycharmProjects/flaskProject/application/routes.py", line 67, in user
    create_pdf(user.name)
  File "/home/alexey/PycharmProjects/flaskProject/application/create_files.py", line 19, in create_pdf
    t = Table(data, 5 * [0.4 * inch], 4 * [0.4 * inch])
  File "/home/alexey/PycharmProjects/flaskProject/venv/lib/python3.8/site-packages/reportlab/platypus/tables.py", line 309, in __init__
    raise ValueError("%s data error - %d rows in data but %d in row heights" % (self.identity(),nrows, len(rowHeights)))
ValueError: <Table@0x7FD26B7C5FD0 6 rows x 2 cols> with cell(0,0) containing
'Name of dimension' data error - 6 rows in data but 4 in row heights
2022-07-26 13:10:57,629 INFO: Microblog startup [in /home/alexey/PycharmProjects/flaskProject/application/__init__.py:30]
2022-07-26 13:11:03,003 ERROR: Exception on /user/b [POST] [in /home/alexey/PycharmProjects/flaskProject/venv/lib/python3.8/site-packages/flask/app.py:1455]
Traceback (most recent call last):
  File "/home/alexey/PycharmProjects/flaskProject/venv/lib/python3.8/site-packages/flask/app.py", line 2077, in wsgi_app
    response = self.full_dispatch_request()
  File "/home/alexey/PycharmProjects/flaskProject/venv/lib/python3.8/site-packages/flask/app.py", line 1525, in full_dispatch_request
    rv = self.handle_user_exception(e)
  File "/home/alexey/PycharmProjects/flaskProject/venv/lib/python3.8/site-packages/flask/app.py", line 1523, in full_dispatch_request
    rv = self.dispatch_request()
  File "/home/alexey/PycharmProjects/flaskProject/venv/lib/python3.8/site-packages/flask/app.py", line 1509, in dispatch_request
    return self.ensure_sync(self.view_functions[rule.endpoint])(**req.view_args)
  File "/home/alexey/PycharmProjects/flaskProject/venv/lib/python3.8/site-packages/flask_login/utils.py", line 303, in decorated_view
    return current_app.ensure_sync(func)(*args, **kwargs)
  File "/home/alexey/PycharmProjects/flaskProject/application/routes.py", line 67, in user
    create_pdf(user.name)
  File "/home/alexey/PycharmProjects/flaskProject/application/create_files.py", line 19, in create_pdf
    t = Table(data,  2* [0.4 * inch], len(a)* [0.4 * inch])
TypeError: object of type 'BaseQuery' has no len()
2022-07-26 13:11:37,749 INFO: Microblog startup [in /home/alexey/PycharmProjects/flaskProject/application/__init__.py:30]
